Workbook

Sheet About
A1: 📘 ABOUT THIS WORKBOOK
A3: 📌 PURPOSE
A4: This workbook is a comprehensive 12-Week Min-Max Training Program tracker designed to log workouts, track progressive overload, and analyze training performance.
A6: 🏋️ PROGRAM STRUCTURE
A7: Attribute | B7: Details
A8: Duration | B8: 12 Weeks
A9: Frequency | B9: 4 Days per Week
A10: Split | B10: Upper/Lower
A11: Block 1 (Weeks 1-6) | B11: Intro Week → Ramp-Up → Deload
A12: Block 2 (Weeks 7-12) | B12: Ramp-Up → Peak → Deload
A13: Training Style | B13: Progressive Overload with RIR-based intensity
A15: 📑 WORKBOOK STRUCTURE
A16: Sheet Name | B16: Purpose
A17: About | B17: Overview and instructions (this page)
A18: 4x Per Week | B18: Master program template with all exercises
A19: Week 1 - Week 12 | B19: Individual weekly workout logs with sets, reps, weight, RIR
A20: Analytics Dashboard | B20: Performance tracking with 9 analytics sections
A21: _DropdownLists | B21: Helper sheet for data validation dropdowns
A23: 📊 ANALYTICS DASHBOARD FEATURES
A24: Section | B24: Description | C24: Chart Type
A25: 1. Weekly Volume Trend | B25: Volume per muscle group over 12 weeks | C25: Stacked Area Chart
A26: 2. Strength Progression (E1RM) | B26: Estimated 1RM trends for main lifts | C26: Line Chart
A27: 3. Reps at a Given Weight | B27: Performance consistency analysis | C27: Scatter Plot
A28: 4. Weekly Bodyweight Trend | B28: Track bodyweight changes with stats | C28: Line Chart
A29: 5. Strength-to-Bodyweight Ratio | B29: Relative strength over time | C29: Dual-Axis Line Chart
A30: 6. Weekly PR Tracker | B30: E1RM summary with PR indicators | C30: Table with Icons
A31: 7. Total Weekly Training Load | B31: Tonnage, sets, reps, avg weight | C31: Summary Table
A32: 8. Exercise-Specific Volume | B32: Volume by movement pattern | C32: Multi-Line Chart
A33: 9. Avg Intensity Tracker | B33: Training intensity as % of 1RM | C33: Line Chart
A35: 🔢 KEY FORMULAS USED
A36: Formula | B36: Calculation
A37: Estimated 1RM (E1RM) | B37: Weight × (1 + Reps ÷ 30)
A38: Volume (per exercise) | B38: Sets × Reps
A39: Total Tonnage | B39: Sets × Weight × Reps
A40: Intensity % | B40: (Working Weight ÷ E1RM) × 100
A41: Strength-to-BW Ratio | B41: E1RM ÷ Bodyweight
A43: 📝 HOW TO USE THIS WORKBOOK
A44: Step | B44: Instructions
A45: Step 1 | B45: Review the '4x Per Week' sheet for the program template
A46: Step 2 | B46: Log each workout in the corresponding Week tab (Week 1-12)
...

Sheet 4x Per Week
B1: The Min-Max Program
Q2: Copyright 2025 by Jeff Nippard. All rights reserved.
B3: IMPORTANT PROGRAM NOTES (PLEASE READ BEFORE STARTING!) ● Due to the lower volume in this program, it's essential that you approach each set with focused intent and high effort. ● Nearly every set in this program should be taken to failure, or 1 rep shy of failure. The only exceptions are in Week 1 (an intro week) and Week 7 (a deload week), where you won't train quite as hard. ● In the program, I use Reps In Reserve (RIR) to indicate which sets you should take to failure. An RIR of 0 means you hit failure (zero reps in the tank). An RIR of 1 means you stop 1 rep shy of failure. ● For heavy compound lifts like the Squat, Barbell Incline Press, Leg Press, and Smith Machine Lunge, an RIR of 0 means you couldn’t complete another rep, but for safety you don't need to actually attempt and fail the final rep unless you want to. ● For all other exercises, an RIR of 0 means that you should actually go for another rep, even if you think you can't get it. On these exercises, go until you physically can't complete the rep and literally fail.
G5: WARM-UP PROTOCOL
G6: Start each workout with about 5 minutes of light cardio to raise your core body temperature. Each exercise includes the recommended number of exercise-specific warm-up sets, which should be light and not fatiguing. For a more detailed breakdown of warm-up protocols, refer to page 13 of the PDF document.
B10: Block 1
B11: Intro Week
B12: Week 1 | C12: Exercise | D12: Last-Set Intensity Technique | E12: Warm-up Sets | F12: Working Sets | G12: Rep Range | H12: Tracking Load and Reps | L12: Failure? | N12: Rest | O12: Substitution Option 1 | P12: Substitution Option 2 | Q12: Notes
H13: Set 1 | J13: Set 2
H14: Load | I14: Reps | J14: Load | K14: Reps | L14: RIR (Set 1) | M14: RIR (Set 2)
B15: Full Body | C15: Lying Leg Curl | D15: N/A | E15: 45659 | F15: 2 | G15: 45816 | L15: 1 | M15: 0 | N15: 1-2 min | O15: Seated Leg Curl | P15: Nordic Ham Curl | Q15: Set the machine so that you get the biggest stretch possible at the bottom. Prevent your butt from popping up as you curl.
C16: Squat (Your Choice) | D16: N/A | E16: 45692 | F16: 2 | G16: 45816 | L16: 3 | M16: 2 | N16: 3-5 min | O16: See Notes | P16: See Notes | Q16: This can be a Barbell Back Squat, Barbell Front Squat, Pendulum Squat, Hack Squat, Belt Squat, or Smith Machine Squat.
C17: Barbell Incline Press | D17: N/A | E17: 45692 | F17: 2 | G17: 45816 | L17: 2 | M17: 1 | N17: 3-5 min | O17: Smith Machine Incline Press | P17: DB Incline Press | Q17: A 30° or 45° bench will work here. Pause for 1 second at the bottom of each rep while maintaining tension on the pecs.
C18: Incline DB Y-Raise | D18: N/A | E18: 0-1 | F18: 1 | G18: 45879 | L18: 0 | M18: N/A | N18: 1-2 min | O18: Cable Y-Raise | P18: Machine Lateral Raise | Q18: Use a 30° incline bench (back against the bench) and lift the weight up and out in a Y shape.
C19: Pull-Up (Wide Grip) | D19: N/A | E19: 45659 | F19: 2 | G19: 45816 | L19: 2 | M19: 1 | N19: 2-3 min | O19: Lat Pulldown (Wide Grip) | P19: 1-Arm Cable Pulldown | Q19: Control the negative and feel your lats pulling apart. Full ROM!
C20: Standing Calf Raise | D20: N/A | E20: 0-1 | F20: 1 | G20: 45816 | L20: 0 | M20: N/A | N20: 1-2 min | O20: Leg Press Calf Press | P20: Donkey Calf Raise | Q20: 1-2 second pause at the bottom of each rep. Instead of just going up onto your toes, think about rolling your ankle back and forth on the balls of your feet.
B21: 1-2 Rest Days
B22: Upper | C22: Close-Grip Lat Pulldown | D22: N/A | E22: 45691 | F22: 2 | G22: 45879 | L22: 2 | M22: 1 | N22: 2-3 min | O22: Close-Grip Pull-Up | P22: 1-Arm Cable Pulldown | Q22: Lean back by ~15° and drive your elbows down as you squeeze your shoulder blades together. This should feel like a mix of lats and mid-traps.
C23: Chest-Supported T-Bar Row | D23: N/A | E23: 45691 | F23: 2 | G23: 45879 | L23: 2 | M23: 1 | N23: 2-3 min | O23: Chest-Supported Machine Row | P23: Chest-Supported DB Row | Q23: Flare elbows out at roughly 45° and squeeze your shoulder blades together hard at the top of each rep.
C24: Machine Shrug | D24: N/A | E24: 45659 | F24: 1 | G24: 45816 | L24: 1 | M24: N/A | N24: 1-2 min | O24: Barbell Shrug | P24: Cable Shrug-In | Q24: Think about shrugging "up to your ears". Use straps, if possible.
C25: Machine Chest Press | D25: N/A | E25: 45692 | F25: 2 | G25: 45879 | L25: 2 | M25: 1 | N25: 3-5 min | O25: Smith Machine Bench Press | P25: DB Bench Press | Q25: 1 second pause at the bottom of each rep while maintaining tension on the pecs.
C26: High-Cable Lateral Raise | D26: N/A | E26: 0-1 | F26: 2 | G26: 45879 | L26: 1 | M26: 0 | N26: 1-2 min | O26: DB Lateral Raise | P26: Machine Lateral Raise | Q26: Set the cable at roughly hip height. Let your hand go slightly past your midline at the bottom of each rep to get a deep stretch on the side delt.
C27: 1-Arm Reverse Pec Deck | D27: N/A | E27: 0-1 | F27: 1 | G27: 45879 | L27: 0 | M27: N/A | N27: 1-2 min | O27: Lying Reverse DB Flye | P27: Reverse Cable Crossover | Q27: Sweep the weight out to create the largest semi-circle possible with your arm.
C28: Cable Crunch | D28: N/A | E28: 0-1 | F28: 2 | G28: 45816 | L28: 1 | M28: 0 | N28: 1-2 min | O28: Weighted Crunch | P28: Machine Crunch | Q28: Round your lower back as you crunch. Maintain a mind-muscle connection with your 6-pack.
B29: Lower | C29: Leg Extension | D29: N/A | E29: 45659 | F29: 2 | G29: 45879 | L29: 1 | M29: 0 | N29: 1-2 min | O29: Reverse Nordic | P29: Sissy Squat | Q29: Set the seat back as far as it will go while still feeling comfortable. Grab the handles as hard as you can to pull your butt down into the seat (using straps can help here).
C30: Barbell RDL | D30: N/A | E30: 45691 | F30: 2 | G30: 45816 | L30: 3 | M30: 2 | N30: 2-3 min | O30: DB RDL | P30: Seated Cable Deadlift | Q30: Stick your glutes straight back as you lower the bar straight down, centered over the middle of your foot. Get a nice deep stretch at the bottom, but keep your spine neutral (don't round forward).
C31: Machine Hip Thrust | D31: N/A | E31: 45692 | F31: 2 | G31: 45816 | L31: 2 | M31: 1 | N31: 2-3 min | O31: Barbell Hip Thrust | P31: 45° Hyperextension | Q31: Squeeze your glutes hard at the top and control the weight on the way down.
C32: Leg Press | D32: N/A | E32: 45692 | F32: 1 | G32: 45816 | L32: 1 | M32: N/A | N32: 2-3 min | O32: Smith Machine Squat | P32: Barbell Squat | Q32: Feet lower on the platform for more quad focus. Get as deep as you can without excessive back rounding.
C33: Standing Calf Raise | D33: N/A | E33: 0-1 | F33: 2 | G33: 45879 | L33: 1 | M33: 0 | N33: 1-2 min | O33: Leg Press Calf Press | P33: Donkey Calf Raise | Q33: 1-2 second pause at the bottom of each rep. Instead of just going up onto your toes, think about rolling your ankle back and forth on the balls of your feet.
B34: Arms/Delts | C34: Bayesian Cable Curl | D34: N/A | E34: 0-1 | F34: 2 | G34: 45816 | L34: 1 | M34: 0 | N34: 1-2 min | O34: Incline DB Curl | P34: Standing DB Curl | Q34: As you curl, optionally lean forward to prevent the cable from hitting your wrist at the top. Control the negative and feel a deep stretch at the bottom of each rep.
C35: Overhead Cable Triceps Extension | D35: N/A | E35: 0-1 | F35: 2 | G35: 45879 | L35: 1 | M35: 0 | N35: 1-2 min | O35: Overhead DB Triceps Extension | P35: Skull Crusher | Q35: Feel a deep stretch on the triceps throughout the entire negative.
C36: Modified Zottman Curl | D36: N/A | E36: 0-1 | F36: 1 | G36: 45879 | L36: 0 | M36: N/A | N36: 1-2 min | O36: DB Hammer Curl | P36: Preacher Hammer Curl | Q36: Hammer curl on the way up and supinated curl (palms up) on the way down.
C37: Cable Triceps Kickback | D37: N/A | E37: 0-1 | F37: 2 | G37: 45879 | L37: 1 | M37: 0 | N37: 1-2 min | O37: Seated Dip Machine | P37: Close-Grip Dip | Q37: Keep your upper arm behind your torso throughout the ROM.
C38: DB Wrist Curl | D38: N/A | E38: 0-1 | F38: 2 | G38: 45879 | L38: 1 | M38: 0 | N38: 1-2 min | O38: Cable Wrist Curl | P38: N/A | Q38: Smooth, controlled reps.
C39: DB Wrist Extension | D39: N/A | E39: 0-1 | F39: 2 | G39: 45879 | L39: 1 | M39: 0 | N39: 1-2 min | O39: Cable Wrist Extension | P39: N/A | Q39: Smooth, controlled reps.
C40: Alternating DB Curl | D40: N/A | E40: 0-1 | F40: 1 | G40: 45816 | L40: 0 | M40: N/A | N40: 1-2 min | O40: Barbell Curl | P40: EZ-Bar Curl | Q40: Slow, controlled reps!
C41: Machine Lateral Raise | D41: N/A | E41: 0-1 | F41: 2 | G41: 45879 | L41: 1 | M41: 0 | N41: 1-2 min | O41: High-Cable Lateral Raise | P41: DB Lateral Raise | Q41: Focus on squeezing your side delt to move the weight.
C42: Dead Hang (optional) | D42: N/A | E42: 0-1 | F42: 2 | G42: N/A | L42: 0 | M42: 0 | N42: 1-2 min | O42: N/A | P42: N/A | Q42: Try to add a few more seconds each week!
B43: 1-2 Rest Days
B46: Week 2 | C46: Exercise | D46: Last-Set Intensity Technique | E46: Warm-up Sets | F46: Working Sets | G46: Rep Range | H46: Tracking Load and Reps | L46: Failure? | N46: Rest | O46: Substitution Option 1 | P46: Substitution Option 2 | Q46: Notes
...

Sheet Analytics Dashboard
A1: 📊 ANALYTICS DASHBOARD
A2: 12-Week Training Program Analytics • Enter workout data in Week tabs to populate charts
A4: 📋 WEEKLY BODYWEIGHT LOG (Auto-populated from Week tabs)
A5: Week | B5: 1 | C5: 2 | D5: 3 | E5: 4 | F5: 5 | G5: 6 | H5: 7 | I5: 8 | J5: 9 | K5: 10 | L5: 11 | M5: 12
A6: Bodyweight (lbs) | B6: ='Week 1'!B39 -> 157.85 | C6: ='Week 2'!B39 -> 0 | D6: ='Week 3'!B39 -> 0 | E6: ='Week 4'!B39 -> 0 | F6: ='Week 5'!B39 -> 0 | G6: ='Week 6'!B39 -> 0 | H6: ='Week 7'!B39 -> 0 | I6: ='Week 8'!B39 -> 0 | J6: ='Week 9'!B39 -> 0 | K6: ='Week 10'!B39 -> 0 | L6: ='Week 11'!B39 -> 0 | M6: ='Week 12'!B39 -> 0
A8: 1️⃣ WEEKLY VOLUME TREND (Per Muscle Group)
A9: 📈 Chart Type: Stacked Area Chart | Shows total weekly training volume for each major muscle group. Helps identify progressive overload and muscle group imbalances.
A11: Muscle Group | B11: Wk 1 | C11: Wk 2 | D11: Wk 3 | E11: Wk 4 | F11: Wk 5 | G11: Wk 6 | H11: Wk 7 | I11: Wk 8 | J11: Wk 9 | K11: Wk 10 | L11: Wk 11 | M11: Wk 12
A12: Quads | B12: =IFERROR(SUMPRODUCT(('Week 1'!E6)*('Week 1'!F6)*('Week 1'!G6))+SUMPRODUCT(('Week 1'!E21)*('Week 1'!F21)*('Week 1'!G21))+SUMPRODUCT(('Week 1'!E24)*('Week 1'!F24)*('Week 1'!G24)), "") -> 1120 | C12: =IFERROR(SUMPRODUCT(('Week 2'!E6)*('Week 2'!F6)*('Week 2'!G6))+SUMPRODUCT(('Week 2'!E21)*('Week 2'!F21)*('Week 2'!G21))+SUMPRODUCT(('Week 2'!E24)*('Week 2'!F24)*('Week 2'!G24)), "") -> 0 | D12: =IFERROR(SUMPRODUCT(('Week 3'!E6)*('Week 3'!F6)*('Week 3'!G6))+SUMPRODUCT(('Week 3'!E21)*('Week 3'!F21)*('Week 3'!G21))+SUMPRODUCT(('Week 3'!E24)*('Week 3'!F24)*('Week 3'!G24)), "") -> 0 | E12: =IFERROR(SUMPRODUCT(('Week 4'!E6)*('Week 4'!F6)*('Week 4'!G6))+SUMPRODUCT(('Week 4'!E21)*('Week 4'!F21)*('Week 4'!G21))+SUMPRODUCT(('Week 4'!E24)*('Week 4'!F24)*('Week 4'!G24)), "") -> 0 | F12: =IFERROR(SUMPRODUCT(('Week 5'!E6)*('Week 5'!F6)*('Week 5'!G6))+SUMPRODUCT(('Week 5'!E21)*('Week 5'!F21)*('Week 5'!G21))+SUMPRODUCT(('Week 5'!E24)*('Week 5'!F24)*('Week 5'!G24)), "") -> 0 | G12: =IFERROR(SUMPRODUCT(('Week 6'!E6)*('Week 6'!F6)*('Week 6'!G6))+SUMPRODUCT(('Week 6'!E21)*('Week 6'!F21)*('Week 6'!G21))+SUMPRODUCT(('Week 6'!E24)*('Week 6'!F24)*('Week 6'!G24)), "") -> 0 | H12: =IFERROR(SUMPRODUCT(('Week 7'!E6)*('Week 7'!F6)*('Week 7'!G6))+SUMPRODUCT(('Week 7'!E21)*('Week 7'!F21)*('Week 7'!G21))+SUMPRODUCT(('Week 7'!E24)*('Week 7'!F24)*('Week 7'!G24)), "") -> 0 | I12: =IFERROR(SUMPRODUCT(('Week 8'!E6)*('Week 8'!F6)*('Week 8'!G6))+SUMPRODUCT(('Week 8'!E21)*('Week 8'!F21)*('Week 8'!G21))+SUMPRODUCT(('Week 8'!E24)*('Week 8'!F24)*('Week 8'!G24)), "") -> 0 | J12: =IFERROR(SUMPRODUCT(('Week 9'!E6)*('Week 9'!F6)*('Week 9'!G6))+SUMPRODUCT(('Week 9'!E21)*('Week 9'!F21)*('Week 9'!G21))+SUMPRODUCT(('Week 9'!E24)*('Week 9'!F24)*('Week 9'!G24)), "") -> 0 | K12: =IFERROR(SUMPRODUCT(('Week 10'!E6)*('Week 10'!F6)*('Week 10'!G6))+SUMPRODUCT(('Week 10'!E21)*('Week 10'!F21)*('Week 10'!G21))+SUMPRODUCT(('Week 10'!E24)*('Week 10'!F24)*('Week 10'!G24)), "") -> 0 | L12: =IFERROR(SUMPRODUCT(('Week 11'!E6)*('Week 11'!F6)*('Week 11'!G6))+SUMPRODUCT(('Week 11'!E21)*('Week 11'!F21)*('Week 11'!G21))+SUMPRODUCT(('Week 11'!E24)*('Week 11'!F24)*('Week 11'!G24)), "") -> 0 | M12: =IFERROR(SUMPRODUCT(('Week 12'!E6)*('Week 12'!F6)*('Week 12'!G6))+SUMPRODUCT(('Week 12'!E21)*('Week 12'!F21)*('Week 12'!G21))+SUMPRODUCT(('Week 12'!E24)*('Week 12'!F24)*('Week 12'!G24)), "") -> 0
A13: Hamstrings | B13: =IFERROR(SUMPRODUCT(('Week 1'!E5)*('Week 1'!F5)*('Week 1'!G5))+SUMPRODUCT(('Week 1'!E22)*('Week 1'!F22)*('Week 1'!G22)), "") -> 2520 | C13: =IFERROR(SUMPRODUCT(('Week 2'!E5)*('Week 2'!F5)*('Week 2'!G5))+SUMPRODUCT(('Week 2'!E22)*('Week 2'!F22)*('Week 2'!G22)), "") -> 0 | D13: =IFERROR(SUMPRODUCT(('Week 3'!E5)*('Week 3'!F5)*('Week 3'!G5))+SUMPRODUCT(('Week 3'!E22)*('Week 3'!F22)*('Week 3'!G22)), "") -> 0 | E13: =IFERROR(SUMPRODUCT(('Week 4'!E5)*('Week 4'!F5)*('Week 4'!G5))+SUMPRODUCT(('Week 4'!E22)*('Week 4'!F22)*('Week 4'!G22)), "") -> 0 | F13: =IFERROR(SUMPRODUCT(('Week 5'!E5)*('Week 5'!F5)*('Week 5'!G5))+SUMPRODUCT(('Week 5'!E22)*('Week 5'!F22)*('Week 5'!G22)), "") -> 0 | G13: =IFERROR(SUMPRODUCT(('Week 6'!E5)*('Week 6'!F5)*('Week 6'!G5))+SUMPRODUCT(('Week 6'!E22)*('Week 6'!F22)*('Week 6'!G22)), "") -> 0 | H13: =IFERROR(SUMPRODUCT(('Week 7'!E5)*('Week 7'!F5)*('Week 7'!G5))+SUMPRODUCT(('Week 7'!E22)*('Week 7'!F22)*('Week 7'!G22)), "") -> 0 | I13: =IFERROR(SUMPRODUCT(('Week 8'!E5)*('Week 8'!F5)*('Week 8'!G5))+SUMPRODUCT(('Week 8'!E22)*('Week 8'!F22)*('Week 8'!G22)), "") -> 0 | J13: =IFERROR(SUMPRODUCT(('Week 9'!E5)*('Week 9'!F5)*('Week 9'!G5))+SUMPRODUCT(('Week 9'!E22)*('Week 9'!F22)*('Week 9'!G22)), "") -> 0 | K13: =IFERROR(SUMPRODUCT(('Week 10'!E5)*('Week 10'!F5)*('Week 10'!G5))+SUMPRODUCT(('Week 10'!E22)*('Week 10'!F22)*('Week 10'!G22)), "") -> 0 | L13: =IFERROR(SUMPRODUCT(('Week 11'!E5)*('Week 11'!F5)*('Week 11'!G5))+SUMPRODUCT(('Week 11'!E22)*('Week 11'!F22)*('Week 11'!G22)), "") -> 0 | M13: =IFERROR(SUMPRODUCT(('Week 12'!E5)*('Week 12'!F5)*('Week 12'!G5))+SUMPRODUCT(('Week 12'!E22)*('Week 12'!F22)*('Week 12'!G22)), "") -> 0
A14: Glutes | B14: =IFERROR(SUMPRODUCT(('Week 1'!E23)*('Week 1'!F23)*('Week 1'!G23)), "") -> 1040 | C14: =IFERROR(SUMPRODUCT(('Week 2'!E23)*('Week 2'!F23)*('Week 2'!G23)), "") -> 0 | D14: =IFERROR(SUMPRODUCT(('Week 3'!E23)*('Week 3'!F23)*('Week 3'!G23)), "") -> 0 | E14: =IFERROR(SUMPRODUCT(('Week 4'!E23)*('Week 4'!F23)*('Week 4'!G23)), "") -> 0 | F14: =IFERROR(SUMPRODUCT(('Week 5'!E23)*('Week 5'!F23)*('Week 5'!G23)), "") -> 0 | G14: =IFERROR(SUMPRODUCT(('Week 6'!E23)*('Week 6'!F23)*('Week 6'!G23)), "") -> 0 | H14: =IFERROR(SUMPRODUCT(('Week 7'!E23)*('Week 7'!F23)*('Week 7'!G23)), "") -> 0 | I14: =IFERROR(SUMPRODUCT(('Week 8'!E23)*('Week 8'!F23)*('Week 8'!G23)), "") -> 0 | J14: =IFERROR(SUMPRODUCT(('Week 9'!E23)*('Week 9'!F23)*('Week 9'!G23)), "") -> 0 | K14: =IFERROR(SUMPRODUCT(('Week 10'!E23)*('Week 10'!F23)*('Week 10'!G23)), "") -> 0 | L14: =IFERROR(SUMPRODUCT(('Week 11'!E23)*('Week 11'!F23)*('Week 11'!G23)), "") -> 0 | M14: =IFERROR(SUMPRODUCT(('Week 12'!E23)*('Week 12'!F23)*('Week 12'!G23)), "") -> 0
A15: Chest | B15: =IFERROR(SUMPRODUCT(('Week 1'!E7)*('Week 1'!F7)*('Week 1'!G7))+SUMPRODUCT(('Week 1'!E16)*('Week 1'!F16)*('Week 1'!G16)), "") -> 1840 | C15: =IFERROR(SUMPRODUCT(('Week 2'!E7)*('Week 2'!F7)*('Week 2'!G7))+SUMPRODUCT(('Week 2'!E16)*('Week 2'!F16)*('Week 2'!G16)), "") -> 0 | D15: =IFERROR(SUMPRODUCT(('Week 3'!E7)*('Week 3'!F7)*('Week 3'!G7))+SUMPRODUCT(('Week 3'!E16)*('Week 3'!F16)*('Week 3'!G16)), "") -> 0 | E15: =IFERROR(SUMPRODUCT(('Week 4'!E7)*('Week 4'!F7)*('Week 4'!G7))+SUMPRODUCT(('Week 4'!E16)*('Week 4'!F16)*('Week 4'!G16)), "") -> 0 | F15: =IFERROR(SUMPRODUCT(('Week 5'!E7)*('Week 5'!F7)*('Week 5'!G7))+SUMPRODUCT(('Week 5'!E16)*('Week 5'!F16)*('Week 5'!G16)), "") -> 0 | G15: =IFERROR(SUMPRODUCT(('Week 6'!E7)*('Week 6'!F7)*('Week 6'!G7))+SUMPRODUCT(('Week 6'!E16)*('Week 6'!F16)*('Week 6'!G16)), "") -> 0 | H15: =IFERROR(SUMPRODUCT(('Week 7'!E7)*('Week 7'!F7)*('Week 7'!G7))+SUMPRODUCT(('Week 7'!E16)*('Week 7'!F16)*('Week 7'!G16)), "") -> 0 | I15: =IFERROR(SUMPRODUCT(('Week 8'!E7)*('Week 8'!F7)*('Week 8'!G7))+SUMPRODUCT(('Week 8'!E16)*('Week 8'!F16)*('Week 8'!G16)), "") -> 0 | J15: =IFERROR(SUMPRODUCT(('Week 9'!E7)*('Week 9'!F7)*('Week 9'!G7))+SUMPRODUCT(('Week 9'!E16)*('Week 9'!F16)*('Week 9'!G16)), "") -> 0 | K15: =IFERROR(SUMPRODUCT(('Week 10'!E7)*('Week 10'!F7)*('Week 10'!G7))+SUMPRODUCT(('Week 10'!E16)*('Week 10'!F16)*('Week 10'!G16)), "") -> 0 | L15: =IFERROR(SUMPRODUCT(('Week 11'!E7)*('Week 11'!F7)*('Week 11'!G7))+SUMPRODUCT(('Week 11'!E16)*('Week 11'!F16)*('Week 11'!G16)), "") -> 0 | M15: =IFERROR(SUMPRODUCT(('Week 12'!E7)*('Week 12'!F7)*('Week 12'!G7))+SUMPRODUCT(('Week 12'!E16)*('Week 12'!F16)*('Week 12'!G16)), "") -> 0
A16: Back | B16: =IFERROR(SUMPRODUCT(('Week 1'!E9)*('Week 1'!F9)*('Week 1'!G9))+SUMPRODUCT(('Week 1'!E13)*('Week 1'!F13)*('Week 1'!G13))+SUMPRODUCT(('Week 1'!E14)*('Week 1'!F14)*('Week 1'!G14))+SUMPRODUCT(('Week 1'!E15)*('Week 1'!F15)*('Week 1'!G15)), "") -> 4410 | C16: =IFERROR(SUMPRODUCT(('Week 2'!E9)*('Week 2'!F9)*('Week 2'!G9))+SUMPRODUCT(('Week 2'!E13)*('Week 2'!F13)*('Week 2'!G13))+SUMPRODUCT(('Week 2'!E14)*('Week 2'!F14)*('Week 2'!G14))+SUMPRODUCT(('Week 2'!E15)*('Week 2'!F15)*('Week 2'!G15)), "") -> 0 | D16: =IFERROR(SUMPRODUCT(('Week 3'!E9)*('Week 3'!F9)*('Week 3'!G9))+SUMPRODUCT(('Week 3'!E13)*('Week 3'!F13)*('Week 3'!G13))+SUMPRODUCT(('Week 3'!E14)*('Week 3'!F14)*('Week 3'!G14))+SUMPRODUCT(('Week 3'!E15)*('Week 3'!F15)*('Week 3'!G15)), "") -> 0 | E16: =IFERROR(SUMPRODUCT(('Week 4'!E9)*('Week 4'!F9)*('Week 4'!G9))+SUMPRODUCT(('Week 4'!E13)*('Week 4'!F13)*('Week 4'!G13))+SUMPRODUCT(('Week 4'!E14)*('Week 4'!F14)*('Week 4'!G14))+SUMPRODUCT(('Week 4'!E15)*('Week 4'!F15)*('Week 4'!G15)), "") -> 0 | F16: =IFERROR(SUMPRODUCT(('Week 5'!E9)*('Week 5'!F9)*('Week 5'!G9))+SUMPRODUCT(('Week 5'!E13)*('Week 5'!F13)*('Week 5'!G13))+SUMPRODUCT(('Week 5'!E14)*('Week 5'!F14)*('Week 5'!G14))+SUMPRODUCT(('Week 5'!E15)*('Week 5'!F15)*('Week 5'!G15)), "") -> 0 | G16: =IFERROR(SUMPRODUCT(('Week 6'!E9)*('Week 6'!F9)*('Week 6'!G9))+SUMPRODUCT(('Week 6'!E13)*('Week 6'!F13)*('Week 6'!G13))+SUMPRODUCT(('Week 6'!E14)*('Week 6'!F14)*('Week 6'!G14))+SUMPRODUCT(('Week 6'!E15)*('Week 6'!F15)*('Week 6'!G15)), "") -> 0 | H16: =IFERROR(SUMPRODUCT(('Week 7'!E9)*('Week 7'!F9)*('Week 7'!G9))+SUMPRODUCT(('Week 7'!E13)*('Week 7'!F13)*('Week 7'!G13))+SUMPRODUCT(('Week 7'!E14)*('Week 7'!F14)*('Week 7'!G14))+SUMPRODUCT(('Week 7'!E15)*('Week 7'!F15)*('Week 7'!G15)), "") -> 0 | I16: =IFERROR(SUMPRODUCT(('Week 8'!E9)*('Week 8'!F9)*('Week 8'!G9))+SUMPRODUCT(('Week 8'!E13)*('Week 8'!F13)*('Week 8'!G13))+SUMPRODUCT(('Week 8'!E14)*('Week 8'!F14)*('Week 8'!G14))+SUMPRODUCT(('Week 8'!E15)*('Week 8'!F15)*('Week 8'!G15)), "") -> 0 | J16: =IFERROR(SUMPRODUCT(('Week 9'!E9)*('Week 9'!F9)*('Week 9'!G9))+SUMPRODUCT(('Week 9'!E13)*('Week 9'!F13)*('Week 9'!G13))+SUMPRODUCT(('Week 9'!E14)*('Week 9'!F14)*('Week 9'!G14))+SUMPRODUCT(('Week 9'!E15)*('Week 9'!F15)*('Week 9'!G15)), "") -> 0 | K16: =IFERROR(SUMPRODUCT(('Week 10'!E9)*('Week 10'!F9)*('Week 10'!G9))+SUMPRODUCT(('Week 10'!E13)*('Week 10'!F13)*('Week 10'!G13))+SUMPRODUCT(('Week 10'!E14)*('Week 10'!F14)*('Week 10'!G14))+SUMPRODUCT(('Week 10'!E15)*('Week 10'!F15)*('Week 10'!G15)), "") -> 0 | L16: =IFERROR(SUMPRODUCT(('Week 11'!E9)*('Week 11'!F9)*('Week 11'!G9))+SUMPRODUCT(('Week 11'!E13)*('Week 11'!F13)*('Week 11'!G13))+SUMPRODUCT(('Week 11'!E14)*('Week 11'!F14)*('Week 11'!G14))+SUMPRODUCT(('Week 11'!E15)*('Week 11'!F15)*('Week 11'!G15)), "") -> 0 | M16: =IFERROR(SUMPRODUCT(('Week 12'!E9)*('Week 12'!F9)*('Week 12'!G9))+SUMPRODUCT(('Week 12'!E13)*('Week 12'!F13)*('Week 12'!G13))+SUMPRODUCT(('Week 12'!E14)*('Week 12'!F14)*('Week 12'!G14))+SUMPRODUCT(('Week 12'!E15)*('Week 12'!F15)*('Week 12'!G15)), "") -> 0
A17: Shoulders | B17: =IFERROR(SUMPRODUCT(('Week 1'!E8)*('Week 1'!F8)*('Week 1'!G8))+SUMPRODUCT(('Week 1'!E17)*('Week 1'!F17)*('Week 1'!G17))+SUMPRODUCT(('Week 1'!E18)*('Week 1'!F18)*('Week 1'!G18))+SUMPRODUCT(('Week 1'!E35)*('Week 1'!F35)*('Week 1'!G35)), "") -> 620 | C17: =IFERROR(SUMPRODUCT(('Week 2'!E8)*('Week 2'!F8)*('Week 2'!G8))+SUMPRODUCT(('Week 2'!E17)*('Week 2'!F17)*('Week 2'!G17))+SUMPRODUCT(('Week 2'!E18)*('Week 2'!F18)*('Week 2'!G18))+SUMPRODUCT(('Week 2'!E35)*('Week 2'!F35)*('Week 2'!G35)), "") -> 0 | D17: =IFERROR(SUMPRODUCT(('Week 3'!E8)*('Week 3'!F8)*('Week 3'!G8))+SUMPRODUCT(('Week 3'!E17)*('Week 3'!F17)*('Week 3'!G17))+SUMPRODUCT(('Week 3'!E18)*('Week 3'!F18)*('Week 3'!G18))+SUMPRODUCT(('Week 3'!E35)*('Week 3'!F35)*('Week 3'!G35)), "") -> 0 | E17: =IFERROR(SUMPRODUCT(('Week 4'!E8)*('Week 4'!F8)*('Week 4'!G8))+SUMPRODUCT(('Week 4'!E17)*('Week 4'!F17)*('Week 4'!G17))+SUMPRODUCT(('Week 4'!E18)*('Week 4'!F18)*('Week 4'!G18))+SUMPRODUCT(('Week 4'!E35)*('Week 4'!F35)*('Week 4'!G35)), "") -> 0 | F17: =IFERROR(SUMPRODUCT(('Week 5'!E8)*('Week 5'!F8)*('Week 5'!G8))+SUMPRODUCT(('Week 5'!E17)*('Week 5'!F17)*('Week 5'!G17))+SUMPRODUCT(('Week 5'!E18)*('Week 5'!F18)*('Week 5'!G18))+SUMPRODUCT(('Week 5'!E35)*('Week 5'!F35)*('Week 5'!G35)), "") -> 0 | G17: =IFERROR(SUMPRODUCT(('Week 6'!E8)*('Week 6'!F8)*('Week 6'!G8))+SUMPRODUCT(('Week 6'!E17)*('Week 6'!F17)*('Week 6'!G17))+SUMPRODUCT(('Week 6'!E18)*('Week 6'!F18)*('Week 6'!G18))+SUMPRODUCT(('Week 6'!E35)*('Week 6'!F35)*('Week 6'!G35)), "") -> 0 | H17: =IFERROR(SUMPRODUCT(('Week 7'!E8)*('Week 7'!F8)*('Week 7'!G8))+SUMPRODUCT(('Week 7'!E17)*('Week 7'!F17)*('Week 7'!G17))+SUMPRODUCT(('Week 7'!E18)*('Week 7'!F18)*('Week 7'!G18))+SUMPRODUCT(('Week 7'!E35)*('Week 7'!F35)*('Week 7'!G35)), "") -> 0 | I17: =IFERROR(SUMPRODUCT(('Week 8'!E8)*('Week 8'!F8)*('Week 8'!G8))+SUMPRODUCT(('Week 8'!E17)*('Week 8'!F17)*('Week 8'!G17))+SUMPRODUCT(('Week 8'!E18)*('Week 8'!F18)*('Week 8'!G18))+SUMPRODUCT(('Week 8'!E35)*('Week 8'!F35)*('Week 8'!G35)), "") -> 0 | J17: =IFERROR(SUMPRODUCT(('Week 9'!E8)*('Week 9'!F8)*('Week 9'!G8))+SUMPRODUCT(('Week 9'!E17)*('Week 9'!F17)*('Week 9'!G17))+SUMPRODUCT(('Week 9'!E18)*('Week 9'!F18)*('Week 9'!G18))+SUMPRODUCT(('Week 9'!E35)*('Week 9'!F35)*('Week 9'!G35)), "") -> 0 | K17: =IFERROR(SUMPRODUCT(('Week 10'!E8)*('Week 10'!F8)*('Week 10'!G8))+SUMPRODUCT(('Week 10'!E17)*('Week 10'!F17)*('Week 10'!G17))+SUMPRODUCT(('Week 10'!E18)*('Week 10'!F18)*('Week 10'!G18))+SUMPRODUCT(('Week 10'!E35)*('Week 10'!F35)*('Week 10'!G35)), "") -> 0 | L17: =IFERROR(SUMPRODUCT(('Week 11'!E8)*('Week 11'!F8)*('Week 11'!G8))+SUMPRODUCT(('Week 11'!E17)*('Week 11'!F17)*('Week 11'!G17))+SUMPRODUCT(('Week 11'!E18)*('Week 11'!F18)*('Week 11'!G18))+SUMPRODUCT(('Week 11'!E35)*('Week 11'!F35)*('Week 11'!G35)), "") -> 0 | M17: =IFERROR(SUMPRODUCT(('Week 12'!E8)*('Week 12'!F8)*('Week 12'!G8))+SUMPRODUCT(('Week 12'!E17)*('Week 12'!F17)*('Week 12'!G17))+SUMPRODUCT(('Week 12'!E18)*('Week 12'!F18)*('Week 12'!G18))+SUMPRODUCT(('Week 12'!E35)*('Week 12'!F35)*('Week 12'!G35)), "") -> 0
A18: Biceps | B18: =IFERROR(SUMPRODUCT(('Week 1'!E28)*('Week 1'!F28)*('Week 1'!G28))+SUMPRODUCT(('Week 1'!E30)*('Week 1'!F30)*('Week 1'!G30))+SUMPRODUCT(('Week 1'!E34)*('Week 1'!F34)*('Week 1'!G34)), "") -> 1475 | C18: =IFERROR(SUMPRODUCT(('Week 2'!E28)*('Week 2'!F28)*('Week 2'!G28))+SUMPRODUCT(('Week 2'!E30)*('Week 2'!F30)*('Week 2'!G30))+SUMPRODUCT(('Week 2'!E34)*('Week 2'!F34)*('Week 2'!G34)), "") -> 0 | D18: =IFERROR(SUMPRODUCT(('Week 3'!E28)*('Week 3'!F28)*('Week 3'!G28))+SUMPRODUCT(('Week 3'!E30)*('Week 3'!F30)*('Week 3'!G30))+SUMPRODUCT(('Week 3'!E34)*('Week 3'!F34)*('Week 3'!G34)), "") -> 0 | E18: =IFERROR(SUMPRODUCT(('Week 4'!E28)*('Week 4'!F28)*('Week 4'!G28))+SUMPRODUCT(('Week 4'!E30)*('Week 4'!F30)*('Week 4'!G30))+SUMPRODUCT(('Week 4'!E34)*('Week 4'!F34)*('Week 4'!G34)), "") -> 0 | F18: =IFERROR(SUMPRODUCT(('Week 5'!E28)*('Week 5'!F28)*('Week 5'!G28))+SUMPRODUCT(('Week 5'!E30)*('Week 5'!F30)*('Week 5'!G30))+SUMPRODUCT(('Week 5'!E34)*('Week 5'!F34)*('Week 5'!G34)), "") -> 0 | G18: =IFERROR(SUMPRODUCT(('Week 6'!E28)*('Week 6'!F28)*('Week 6'!G28))+SUMPRODUCT(('Week 6'!E30)*('Week 6'!F30)*('Week 6'!G30))+SUMPRODUCT(('Week 6'!E34)*('Week 6'!F34)*('Week 6'!G34)), "") -> 0 | H18: =IFERROR(SUMPRODUCT(('Week 7'!E28)*('Week 7'!F28)*('Week 7'!G28))+SUMPRODUCT(('Week 7'!E30)*('Week 7'!F30)*('Week 7'!G30))+SUMPRODUCT(('Week 7'!E34)*('Week 7'!F34)*('Week 7'!G34)), "") -> 0 | I18: =IFERROR(SUMPRODUCT(('Week 8'!E28)*('Week 8'!F28)*('Week 8'!G28))+SUMPRODUCT(('Week 8'!E30)*('Week 8'!F30)*('Week 8'!G30))+SUMPRODUCT(('Week 8'!E34)*('Week 8'!F34)*('Week 8'!G34)), "") -> 0 | J18: =IFERROR(SUMPRODUCT(('Week 9'!E28)*('Week 9'!F28)*('Week 9'!G28))+SUMPRODUCT(('Week 9'!E30)*('Week 9'!F30)*('Week 9'!G30))+SUMPRODUCT(('Week 9'!E34)*('Week 9'!F34)*('Week 9'!G34)), "") -> 0 | K18: =IFERROR(SUMPRODUCT(('Week 10'!E28)*('Week 10'!F28)*('Week 10'!G28))+SUMPRODUCT(('Week 10'!E30)*('Week 10'!F30)*('Week 10'!G30))+SUMPRODUCT(('Week 10'!E34)*('Week 10'!F34)*('Week 10'!G34)), "") -> 0 | L18: =IFERROR(SUMPRODUCT(('Week 11'!E28)*('Week 11'!F28)*('Week 11'!G28))+SUMPRODUCT(('Week 11'!E30)*('Week 11'!F30)*('Week 11'!G30))+SUMPRODUCT(('Week 11'!E34)*('Week 11'!F34)*('Week 11'!G34)), "") -> 0 | M18: =IFERROR(SUMPRODUCT(('Week 12'!E28)*('Week 12'!F28)*('Week 12'!G28))+SUMPRODUCT(('Week 12'!E30)*('Week 12'!F30)*('Week 12'!G30))+SUMPRODUCT(('Week 12'!E34)*('Week 12'!F34)*('Week 12'!G34)), "") -> 0
A19: Triceps | B19: =IFERROR(SUMPRODUCT(('Week 1'!E29)*('Week 1'!F29)*('Week 1'!G29))+SUMPRODUCT(('Week 1'!E31)*('Week 1'!F31)*('Week 1'!G31)), "") -> 670 | C19: =IFERROR(SUMPRODUCT(('Week 2'!E29)*('Week 2'!F29)*('Week 2'!G29))+SUMPRODUCT(('Week 2'!E31)*('Week 2'!F31)*('Week 2'!G31)), "") -> 0 | D19: =IFERROR(SUMPRODUCT(('Week 3'!E29)*('Week 3'!F29)*('Week 3'!G29))+SUMPRODUCT(('Week 3'!E31)*('Week 3'!F31)*('Week 3'!G31)), "") -> 0 | E19: =IFERROR(SUMPRODUCT(('Week 4'!E29)*('Week 4'!F29)*('Week 4'!G29))+SUMPRODUCT(('Week 4'!E31)*('Week 4'!F31)*('Week 4'!G31)), "") -> 0 | F19: =IFERROR(SUMPRODUCT(('Week 5'!E29)*('Week 5'!F29)*('Week 5'!G29))+SUMPRODUCT(('Week 5'!E31)*('Week 5'!F31)*('Week 5'!G31)), "") -> 0 | G19: =IFERROR(SUMPRODUCT(('Week 6'!E29)*('Week 6'!F29)*('Week 6'!G29))+SUMPRODUCT(('Week 6'!E31)*('Week 6'!F31)*('Week 6'!G31)), "") -> 0 | H19: =IFERROR(SUMPRODUCT(('Week 7'!E29)*('Week 7'!F29)*('Week 7'!G29))+SUMPRODUCT(('Week 7'!E31)*('Week 7'!F31)*('Week 7'!G31)), "") -> 0 | I19: =IFERROR(SUMPRODUCT(('Week 8'!E29)*('Week 8'!F29)*('Week 8'!G29))+SUMPRODUCT(('Week 8'!E31)*('Week 8'!F31)*('Week 8'!G31)), "") -> 0 | J19: =IFERROR(SUMPRODUCT(('Week 9'!E29)*('Week 9'!F29)*('Week 9'!G29))+SUMPRODUCT(('Week 9'!E31)*('Week 9'!F31)*('Week 9'!G31)), "") -> 0 | K19: =IFERROR(SUMPRODUCT(('Week 10'!E29)*('Week 10'!F29)*('Week 10'!G29))+SUMPRODUCT(('Week 10'!E31)*('Week 10'!F31)*('Week 10'!G31)), "") -> 0 | L19: =IFERROR(SUMPRODUCT(('Week 11'!E29)*('Week 11'!F29)*('Week 11'!G29))+SUMPRODUCT(('Week 11'!E31)*('Week 11'!F31)*('Week 11'!G31)), "") -> 0 | M19: =IFERROR(SUMPRODUCT(('Week 12'!E29)*('Week 12'!F29)*('Week 12'!G29))+SUMPRODUCT(('Week 12'!E31)*('Week 12'!F31)*('Week 12'!G31)), "") -> 0
A20: Calves | B20: =IFERROR(SUMPRODUCT(('Week 1'!E10)*('Week 1'!F10)*('Week 1'!G10))+SUMPRODUCT(('Week 1'!E25)*('Week 1'!F25)*('Week 1'!G25)), "") -> 2880 | C20: =IFERROR(SUMPRODUCT(('Week 2'!E10)*('Week 2'!F10)*('Week 2'!G10))+SUMPRODUCT(('Week 2'!E25)*('Week 2'!F25)*('Week 2'!G25)), "") -> 0 | D20: =IFERROR(SUMPRODUCT(('Week 3'!E10)*('Week 3'!F10)*('Week 3'!G10))+SUMPRODUCT(('Week 3'!E25)*('Week 3'!F25)*('Week 3'!G25)), "") -> 0 | E20: =IFERROR(SUMPRODUCT(('Week 4'!E10)*('Week 4'!F10)*('Week 4'!G10))+SUMPRODUCT(('Week 4'!E25)*('Week 4'!F25)*('Week 4'!G25)), "") -> 0 | F20: =IFERROR(SUMPRODUCT(('Week 5'!E10)*('Week 5'!F10)*('Week 5'!G10))+SUMPRODUCT(('Week 5'!E25)*('Week 5'!F25)*('Week 5'!G25)), "") -> 0 | G20: =IFERROR(SUMPRODUCT(('Week 6'!E10)*('Week 6'!F10)*('Week 6'!G10))+SUMPRODUCT(('Week 6'!E25)*('Week 6'!F25)*('Week 6'!G25)), "") -> 0 | H20: =IFERROR(SUMPRODUCT(('Week 7'!E10)*('Week 7'!F10)*('Week 7'!G10))+SUMPRODUCT(('Week 7'!E25)*('Week 7'!F25)*('Week 7'!G25)), "") -> 0 | I20: =IFERROR(SUMPRODUCT(('Week 8'!E10)*('Week 8'!F10)*('Week 8'!G10))+SUMPRODUCT(('Week 8'!E25)*('Week 8'!F25)*('Week 8'!G25)), "") -> 0 | J20: =IFERROR(SUMPRODUCT(('Week 9'!E10)*('Week 9'!F10)*('Week 9'!G10))+SUMPRODUCT(('Week 9'!E25)*('Week 9'!F25)*('Week 9'!G25)), "") -> 0 | K20: =IFERROR(SUMPRODUCT(('Week 10'!E10)*('Week 10'!F10)*('Week 10'!G10))+SUMPRODUCT(('Week 10'!E25)*('Week 10'!F25)*('Week 10'!G25)), "") -> 0 | L20: =IFERROR(SUMPRODUCT(('Week 11'!E10)*('Week 11'!F10)*('Week 11'!G10))+SUMPRODUCT(('Week 11'!E25)*('Week 11'!F25)*('Week 11'!G25)), "") -> 0 | M20: =IFERROR(SUMPRODUCT(('Week 12'!E10)*('Week 12'!F10)*('Week 12'!G10))+SUMPRODUCT(('Week 12'!E25)*('Week 12'!F25)*('Week 12'!G25)), "") -> 0
A21: 💡 Volume = Working Sets × Working Reps × Working Weight. Enter data in weekly tabs to auto-calculate.
A23: 2️⃣ STRENGTH PROGRESSION (Estimated 1RM)
A24: 📈 Chart Type: Line Chart | Tracks estimated 1RM for the main lifts to show strength progression over the 12-week block. Formula: Weight × (1 + Reps/30)
A26: Main Lift | B26: Wk 1 | C26: Wk 2 | D26: Wk 3 | E26: Wk 4 | F26: Wk 5 | G26: Wk 6 | H26: Wk 7 | I26: Wk 8 | J26: Wk 9 | K26: Wk 10 | L26: Wk 11 | M26: Wk 12
A27: Squat (Your Choice) | B27: =IFERROR(IF('Week 1'!F6<>"", 'Week 1'!F6*(1+'Week 1'!G6/30), ""), "") -> 88.666667 | C27: =IFERROR(IF('Week 2'!F6<>"", 'Week 2'!F6*(1+'Week 2'!G6/30), ""), "") | D27: =IFERROR(IF('Week 3'!F6<>"", 'Week 3'!F6*(1+'Week 3'!G6/30), ""), "") | E27: =IFERROR(IF('Week 4'!F6<>"", 'Week 4'!F6*(1+'Week 4'!G6/30), ""), "") | F27: =IFERROR(IF('Week 5'!F6<>"", 'Week 5'!F6*(1+'Week 5'!G6/30), ""), "") | G27: =IFERROR(IF('Week 6'!F6<>"", 'Week 6'!F6*(1+'Week 6'!G6/30), ""), "") | H27: =IFERROR(IF('Week 7'!F6<>"", 'Week 7'!F6*(1+'Week 7'!G6/30), ""), "") | I27: =IFERROR(IF('Week 8'!F6<>"", 'Week 8'!F6*(1+'Week 8'!G6/30), ""), "") | J27: =IFERROR(IF('Week 9'!F6<>"", 'Week 9'!F6*(1+'Week 9'!G6/30), ""), "") | K27: =IFERROR(IF('Week 10'!F6<>"", 'Week 10'!F6*(1+'Week 10'!G6/30), ""), "") | L27: =IFERROR(IF('Week 11'!F6<>"", 'Week 11'!F6*(1+'Week 11'!G6/30), ""), "") | M27: =IFERROR(IF('Week 12'!F6<>"", 'Week 12'!F6*(1+'Week 12'!G6/30), ""), "")
A28: Barbell Incline Press | B28: =IFERROR(IF('Week 1'!F7<>"", 'Week 1'!F7*(1+'Week 1'!G7/30), ""), "") -> 31.666667 | C28: =IFERROR(IF('Week 2'!F7<>"", 'Week 2'!F7*(1+'Week 2'!G7/30), ""), "") | D28: =IFERROR(IF('Week 3'!F7<>"", 'Week 3'!F7*(1+'Week 3'!G7/30), ""), "") | E28: =IFERROR(IF('Week 4'!F7<>"", 'Week 4'!F7*(1+'Week 4'!G7/30), ""), "") | F28: =IFERROR(IF('Week 5'!F7<>"", 'Week 5'!F7*(1+'Week 5'!G7/30), ""), "") | G28: =IFERROR(IF('Week 6'!F7<>"", 'Week 6'!F7*(1+'Week 6'!G7/30), ""), "") | H28: =IFERROR(IF('Week 7'!F7<>"", 'Week 7'!F7*(1+'Week 7'!G7/30), ""), "") | I28: =IFERROR(IF('Week 8'!F7<>"", 'Week 8'!F7*(1+'Week 8'!G7/30), ""), "") | J28: =IFERROR(IF('Week 9'!F7<>"", 'Week 9'!F7*(1+'Week 9'!G7/30), ""), "") | K28: =IFERROR(IF('Week 10'!F7<>"", 'Week 10'!F7*(1+'Week 10'!G7/30), ""), "") | L28: =IFERROR(IF('Week 11'!F7<>"", 'Week 11'!F7*(1+'Week 11'!G7/30), ""), "") | M28: =IFERROR(IF('Week 12'!F7<>"", 'Week 12'!F7*(1+'Week 12'!G7/30), ""), "")
A29: Barbell RDL | B29: =IFERROR(IF('Week 1'!F22<>"", 'Week 1'!F22*(1+'Week 1'!G22/30), ""), "") -> 93.333333 | C29: =IFERROR(IF('Week 2'!F22<>"", 'Week 2'!F22*(1+'Week 2'!G22/30), ""), "") | D29: =IFERROR(IF('Week 3'!F22<>"", 'Week 3'!F22*(1+'Week 3'!G22/30), ""), "") | E29: =IFERROR(IF('Week 4'!F22<>"", 'Week 4'!F22*(1+'Week 4'!G22/30), ""), "") | F29: =IFERROR(IF('Week 5'!F22<>"", 'Week 5'!F22*(1+'Week 5'!G22/30), ""), "") | G29: =IFERROR(IF('Week 6'!F22<>"", 'Week 6'!F22*(1+'Week 6'!G22/30), ""), "") | H29: =IFERROR(IF('Week 7'!F22<>"", 'Week 7'!F22*(1+'Week 7'!G22/30), ""), "") | I29: =IFERROR(IF('Week 8'!F22<>"", 'Week 8'!F22*(1+'Week 8'!G22/30), ""), "") | J29: =IFERROR(IF('Week 9'!F22<>"", 'Week 9'!F22*(1+'Week 9'!G22/30), ""), "") | K29: =IFERROR(IF('Week 10'!F22<>"", 'Week 10'!F22*(1+'Week 10'!G22/30), ""), "") | L29: =IFERROR(IF('Week 11'!F22<>"", 'Week 11'!F22*(1+'Week 11'!G22/30), ""), "") | M29: =IFERROR(IF('Week 12'!F22<>"", 'Week 12'!F22*(1+'Week 12'!G22/30), ""), "")
A30: Leg Press | B30: =IFERROR(IF('Week 1'!F24<>"", 'Week 1'!F24*(1+'Week 1'!G24/30), ""), "") | C30: =IFERROR(IF('Week 2'!F24<>"", 'Week 2'!F24*(1+'Week 2'!G24/30), ""), "") | D30: =IFERROR(IF('Week 3'!F24<>"", 'Week 3'!F24*(1+'Week 3'!G24/30), ""), "") | E30: =IFERROR(IF('Week 4'!F24<>"", 'Week 4'!F24*(1+'Week 4'!G24/30), ""), "") | F30: =IFERROR(IF('Week 5'!F24<>"", 'Week 5'!F24*(1+'Week 5'!G24/30), ""), "") | G30: =IFERROR(IF('Week 6'!F24<>"", 'Week 6'!F24*(1+'Week 6'!G24/30), ""), "") | H30: =IFERROR(IF('Week 7'!F24<>"", 'Week 7'!F24*(1+'Week 7'!G24/30), ""), "") | I30: =IFERROR(IF('Week 8'!F24<>"", 'Week 8'!F24*(1+'Week 8'!G24/30), ""), "") | J30: =IFERROR(IF('Week 9'!F24<>"", 'Week 9'!F24*(1+'Week 9'!G24/30), ""), "") | K30: =IFERROR(IF('Week 10'!F24<>"", 'Week 10'!F24*(1+'Week 10'!G24/30), ""), "") | L30: =IFERROR(IF('Week 11'!F24<>"", 'Week 11'!F24*(1+'Week 11'!G24/30), ""), "") | M30: =IFERROR(IF('Week 12'!F24<>"", 'Week 12'!F24*(1+'Week 12'!G24/30), ""), "")
A31: Pull-Up (Wide Grip) | B31: =IFERROR(IF('Week 1'!F9<>"", 'Week 1'!F9*(1+'Week 1'!G9/30), ""), "") -> 88.666667 | C31: =IFERROR(IF('Week 2'!F9<>"", 'Week 2'!F9*(1+'Week 2'!G9/30), ""), "") | D31: =IFERROR(IF('Week 3'!F9<>"", 'Week 3'!F9*(1+'Week 3'!G9/30), ""), "") | E31: =IFERROR(IF('Week 4'!F9<>"", 'Week 4'!F9*(1+'Week 4'!G9/30), ""), "") | F31: =IFERROR(IF('Week 5'!F9<>"", 'Week 5'!F9*(1+'Week 5'!G9/30), ""), "") | G31: =IFERROR(IF('Week 6'!F9<>"", 'Week 6'!F9*(1+'Week 6'!G9/30), ""), "") | H31: =IFERROR(IF('Week 7'!F9<>"", 'Week 7'!F9*(1+'Week 7'!G9/30), ""), "") | I31: =IFERROR(IF('Week 8'!F9<>"", 'Week 8'!F9*(1+'Week 8'!G9/30), ""), "") | J31: =IFERROR(IF('Week 9'!F9<>"", 'Week 9'!F9*(1+'Week 9'!G9/30), ""), "") | K31: =IFERROR(IF('Week 10'!F9<>"", 'Week 10'!F9*(1+'Week 10'!G9/30), ""), "") | L31: =IFERROR(IF('Week 11'!F9<>"", 'Week 11'!F9*(1+'Week 11'!G9/30), ""), "") | M31: =IFERROR(IF('Week 12'!F9<>"", 'Week 12'!F9*(1+'Week 12'!G9/30), ""), "")
A32: 💡 Estimated 1RM = Working Weight × (1 + Working Reps / 30). Epley formula for strength estimation.
A34: 3️⃣ REPS AT A GIVEN WEIGHT (Performance Consistency)
A35: 📈 Chart Type: Scatter Plot | Shows how many reps you perform at repeated weights. Increasing reps at the same weight indicates strength gains.
A37: Exercise | B37: Weight | C37: Reps (Earliest) | D37: Reps (Latest) | E37: Rep Gain
A38: Squat (Your Choice) | E38: =IF(AND(C38<>"",D38<>""),D38-C38,"")
A39: Barbell Incline Press | E39: =IF(AND(C39<>"",D39<>""),D39-C39,"")
A40: Barbell RDL | E40: =IF(AND(C40<>"",D40<>""),D40-C40,"")
A41: Leg Press | E41: =IF(AND(C41<>"",D41<>""),D41-C41,"")
A42: Pull-Up (Wide Grip) | E42: =IF(AND(C42<>"",D42<>""),D42-C42,"")
A43: 💡 Enter the weight you want to track and your earliest/latest rep counts at that weight. Rep Gain auto-calculates.
A45: 4️⃣ WEEKLY BODYWEIGHT TREND
A46: 📈 Chart Type: Line Chart | Displays weekly bodyweight to contextualize strength and volume changes. Data sourced from Bodyweight Log above (Row 6).
A48: Starting Weight | B48: Current Weight | C48: Change (lbs) | D48: Change (%) | E48: Average | F48: Min/Max
A49: =IF(B6<>"",B6,"-") -> 157.85 | B49: {=IF(COUNTA(B6:M6)>0,INDEX(B6:M6,1,COUNTA(B6:M6)),"-")} -> 0 | C49: =IF(AND(ISNUMBER(A49),ISNUMBER(B49)),B49-A49,"-") -> -157.85 | D49: =IF(AND(ISNUMBER(A49),ISNUMBER(C49)),C49/A49,"-") -> -1 | E49: =IF(COUNTA(B6:M6)>0,AVERAGE(B6:M6),"-") -> 13.154167 | F49: =IF(COUNTA(B6:M6)>0,MIN(B6:M6)&" / "&MAX(B6:M6),"-") -> 0 / 157.85
...

Sheet _DropdownLists
A1: 1 | B1: Lying Leg Curl
A2: 2 | B2: Seated Leg Curl
A3: 3 | B3: Nordic Ham Curl
B4: Squat (Your Choice)
B5: Barbell Back Squat
B6: Front Squat
B7: Pendulum Squat
B8: Hack Squat
B9: Belt Squat
B10: Smith Machine Squat
B11: Barbell Incline Press
B12: Smith Machine Incline Press
B13: DB Incline Press
B14: Incline DB Y-Raise
B15: Cable Y-Raise
... B73: Dead Hang (optional)

Sheet Week 1
A1: WEEK 1 WORKOUT TRACKER
A3: Exercise | B3: Warm-Up Sets | C3: Warm-Up Reps | D3: Warm-Up Weight | E3: Working Sets | F3: Working Weight | G3: Working Reps
A4: Full Body
A5: Lying Leg Curl | B5: 2 | C5: 10 | D5: 50 | E5: 2 | F5: 70 | G5: 8
A6: Hack Squat | B6: 2 | C6: 10 | D6: 45 | E6: 2 | F6: 70 | G6: 8
A7: DB Incline Press | B7: 2 | C7: 8 | D7: 20 | E7: 2 | F7: 25 | G7: 8
A8: Incline DB Y-Raise | B8: 2 | C8: 8 | D8: 5 | E8: 2 | F8: 7.5 | G8: 8
A9: Pull-Up (Wide Grip) | B9: 1 | C9: 10 | D9: 60 | E9: 2 | F9: 70 | G9: 8
A10: Standing Calf Raise
A12: Upper
A13: Close-Grip Lat Pulldown | B13: 2 | C13: 10 | D13: 50 | E13: 2 | F13: 70 | G13: 8
A14: Chest-Supported T-Bar Row | B14: 1 | C14: 10 | D14: 45 | E14: 2 | F14: 70 | G14: 8
A15: Barbell Shrug | E15: 3 | F15: 35 | G15: 10
A16: Machine Chest Press | B16: 1 | C16: 10 | D16: 50 | E16: 3 | F16: 60 | G16: 8
A17: High-Cable Lateral Raise | B17: 1 | C17: 10 | D17: 20 | E17: 2 | F17: 25 | G17: 10
A18: 1-Arm Reverse Pec Deck
A19: Machine Crunch | E19: 2 | G19: 8
A21: Lower
A22: Leg Extension | B22: 2 | C22: 10 | D22: 50 | E22: 2 | F22: 70 | G22: 10
A23: Barbell RDL | B23: 2 | C23: 8 | D23: 45 | E23: 2 | F23: 65 | G23: 8
A24: Machine Hip Thrust
A25: Leg Press | B25: 2 | C25: 10 | D25: 90 | E25: 2 | F25: 180 | G25: 8
A26: Standing Calf Raise | E26: 3 | F26: 45 | G26: 10
A28: Arms/Delts
A29: Incline DB Curl | B29: 1 | C29: 10 | D29: 15 | E29: 2 | F29: 17.5 | G29: 10
A30: Overhead Cable Triceps Extension | B30: 1 | C30: 10 | D30: 40 | E30: 2 | F30: 55 | G30: 10
A31: Modified Zottman Curl | B31: 1 | C31: 10 | D31: 17.5 | E31: 2 | F31: 20 | G31: 8
A32: Cable Triceps Kickback | B32: 1 | C32: 10 | D32: 20 | E32: 2 | F32: 25 | G32: 8
A33: DB Wrist Curl | E33: 3 | F33: 15 | G33: 10
A34: DB Wrist Extension | E34: 3 | F34: 12.5 | G34: 10
A35: Alternating DB Curl
A36: Machine Lateral Raise | E36: 2 | F36: 20 | G36: 10
A37: Dead Hang (optional)
A39: End of Week Bodyweight: | B39: 157.85 | C39: lbs

Sheet Week 2
A1: WEEK 2 WORKOUT TRACKER
A3: Exercise | B3: Warm-Up Sets | C3: Warm-Up Reps | D3: Warm-Up Weight | E3: Working Sets | F3: Working Weight | G3: Working Reps
A4: Full Body
A5: Lying Leg Curl
A6: Squat (Your Choice)
A7: Barbell Incline Press
A8: Incline DB Y-Raise
A9: Pull-Up (Wide Grip)
A10: Standing Calf Raise
A12: Upper
A13: Close-Grip Lat Pulldown
A14: Chest-Supported T-Bar Row
A15: Machine Shrug
A16: Machine Chest Press
... A37: Dead Hang (optional)
A39: End of Week Bodyweight: | C39: lbs

Sheet Week 3
A1: WEEK 3 WORKOUT TRACKER
A3: Exercise | B3: Warm-Up Sets | C3: Warm-Up Reps | D3: Warm-Up Weight | E3: Working Sets | F3: Working Weight | G3: Working Reps
A4: Full Body
A5: Lying Leg Curl
A6: Squat (Your Choice)
A7: Barbell Incline Press
A8: Incline DB Y-Raise
A9: Pull-Up (Wide Grip)
A10: Standing Calf Raise
A12: Upper
A13: Close-Grip Lat Pulldown
A14: Chest-Supported T-Bar Row
A15: Machine Shrug
A16: Machine Chest Press
... A37: Dead Hang (optional)
A39: End of Week Bodyweight: | C39: lbs

Sheet Week 4
A1: WEEK 4 WORKOUT TRACKER
A3: Exercise | B3: Warm-Up Sets | C3: Warm-Up Reps | D3: Warm-Up Weight | E3: Working Sets | F3: Working Weight | G3: Working Reps
A4: Full Body
A5: Lying Leg Curl
A6: Squat (Your Choice)
A7: Barbell Incline Press
A8: Incline DB Y-Raise
A9: Pull-Up (Wide Grip)
A10: Standing Calf Raise
A12: Upper
A13: Close-Grip Lat Pulldown
A14: Chest-Supported T-Bar Row
A15: Machine Shrug
A16: Machine Chest Press
... A37: Dead Hang (optional)
A39: End of Week Bodyweight: | C39: lbs

Sheet Week 5
A1: WEEK 5 WORKOUT TRACKER
A3: Exercise | B3: Warm-Up Sets | C3: Warm-Up Reps | D3: Warm-Up Weight | E3: Working Sets | F3: Working Weight | G3: Working Reps
A4: Full Body
A5: Lying Leg Curl
A6: Squat (Your Choice)
A7: Barbell Incline Press
A8: Incline DB Y-Raise
A9: Pull-Up (Wide Grip)
A10: Standing Calf Raise
A12: Upper
A13: Close-Grip Lat Pulldown
A14: Chest-Supported T-Bar Row
A15: Machine Shrug
A16: Machine Chest Press
... A37: Dead Hang (optional)
A39: End of Week Bodyweight: | C39: lbs

Sheet Week 6
A1: WEEK 6 WORKOUT TRACKER
A3: Exercise | B3: Warm-Up Sets | C3: Warm-Up Reps | D3: Warm-Up Weight | E3: Working Sets | F3: Working Weight | G3: Working Reps
A4: Full Body
A5: Lying Leg Curl
A6: Squat (Your Choice)
A7: Barbell Incline Press
A8: Incline DB Y-Raise
A9: Pull-Up (Wide Grip)
A10: Standing Calf Raise
A12: Upper
A13: Close-Grip Lat Pulldown
A14: Chest-Supported T-Bar Row
A15: Machine Shrug
A16: Machine Chest Press
... A37: Dead Hang (optional)
A39: End of Week Bodyweight: | C39: lbs

Sheet Week 7
A1: WEEK 7 WORKOUT TRACKER
A3: Exercise | B3: Warm-Up Sets | C3: Warm-Up Reps | D3: Warm-Up Weight | E3: Working Sets | F3: Working Weight | G3: Working Reps
A4: Full Body
A5: Lying Leg Curl
A6: Squat (Your Choice)
A7: Barbell Incline Press
A8: Incline DB Y-Raise
A9: Pull-Up (Wide Grip)
A10: Standing Calf Raise
A12: Upper
A13: Close-Grip Lat Pulldown
A14: Chest-Supported T-Bar Row
A15: Machine Shrug
A16: Machine Chest Press
... A37: Dead Hang (optional)
A39: End of Week Bodyweight: | C39: lbs

Sheet Week 8
A1: WEEK 8 WORKOUT TRACKER
A3: Exercise | B3: Warm-Up Sets | C3: Warm-Up Reps | D3: Warm-Up Weight | E3: Working Sets | F3: Working Weight | G3: Working Reps
A4: Full Body
A5: Lying Leg Curl
A6: Squat (Your Choice)
A7: Barbell Incline Press
A8: Incline DB Y-Raise
A9: Pull-Up (Wide Grip)
A10: Standing Calf Raise
A12: Upper
A13: Close-Grip Lat Pulldown
A14: Chest-Supported T-Bar Row
A15: Machine Shrug
A16: Machine Chest Press
... A37: Dead Hang (optional)
A39: End of Week Bodyweight: | C39: lbs

Sheet Week 9
A1: WEEK 9 WORKOUT TRACKER
A3: Exercise | B3: Warm-Up Sets | C3: Warm-Up Reps | D3: Warm-Up Weight | E3: Working Sets | F3: Working Weight | G3: Working Reps
A4: Full Body
A5: Lying Leg Curl
A6: Squat (Your Choice)
A7: Barbell Incline Press
A8: Incline DB Y-Raise
A9: Pull-Up (Wide Grip)
A10: Standing Calf Raise
A12: Upper
A13: Close-Grip Lat Pulldown
A14: Chest-Supported T-Bar Row
A15: Machine Shrug
A16: Machine Chest Press
... A37: Dead Hang (optional)
A39: End of Week Bodyweight: | C39: lbs

Sheet Week 10
A1: WEEK 10 WORKOUT TRACKER
A3: Exercise | B3: Warm-Up Sets | C3: Warm-Up Reps | D3: Warm-Up Weight | E3: Working Sets | F3: Working Weight | G3: Working Reps
A4: Full Body
A5: Lying Leg Curl
A6: Squat (Your Choice)
A7: Barbell Incline Press
A8: Incline DB Y-Raise
A9: Pull-Up (Wide Grip)
A10: Standing Calf Raise
A12: Upper
A13: Close-Grip Lat Pulldown
A14: Chest-Supported T-Bar Row
A15: Machine Shrug
A16: Machine Chest Press
... A37: Dead Hang (optional)
A39: End of Week Bodyweight: | C39: lbs

Sheet Week 11
A1: WEEK 11 WORKOUT TRACKER
A3: Exercise | B3: Warm-Up Sets | C3: Warm-Up Reps | D3: Warm-Up Weight | E3: Working Sets | F3: Working Weight | G3: Working Reps
A4: Full Body
A5: Lying Leg Curl
A6: Squat (Your Choice)
A7: Barbell Incline Press
A8: Incline DB Y-Raise
A9: Pull-Up (Wide Grip)
A10: Standing Calf Raise
A12: Upper
A13: Close-Grip Lat Pulldown
A14: Chest-Supported T-Bar Row
A15: Machine Shrug
A16: Machine Chest Press
... A37: Dead Hang (optional)
A39: End of Week Bodyweight: | C39: lbs

Sheet Week 12
A1: WEEK 12 WORKOUT TRACKER
A3: Exercise | B3: Warm-Up Sets | C3: Warm-Up Reps | D3: Warm-Up Weight | E3: Working Sets | F3: Working Weight | G3: Working Reps
A4: Full Body
A5: Lying Leg Curl
A6: Squat (Your Choice)
A7: Barbell Incline Press
A8: Incline DB Y-Raise
A9: Pull-Up (Wide Grip)
A10: Standing Calf Raise
A12: Upper
A13: Close-Grip Lat Pulldown
A14: Chest-Supported T-Bar Row
A15: Machine Shrug
A16: Machine Chest Press
... A37: Dead Hang (optional)
A39: End of Week Bodyweight: | C39: lbs
